<?xml version="1.0"?>
<robot name="LR4_R560">
    <link name="robot_base">
        <inertial>
            <origin xyz="0.141673 -0.000165 0.081066" rpy="0 0 0"/>
            <mass value="10.0"/>
            <inertia ixx="0.05" ixy="0.0" ixz="0.0"
                    iyy="0.05" iyz="0.0"
                    izz="0.08"/>
        </inertial>
        <collision name="LR4_R560">
            <origin xyz="0.000000 -0.000165 0.081066" rpy="-3.060188 4.708523 -0.081638" />
            <geometry>
                <mesh filename="package://linghou_description/meshes/xarm7_with_gripper_robot_base_coll_1.dae" />
            </geometry>
        </collision>
        <collision name="LR4_R560">
            <origin xyz="0.000000 -0.000165 0.081066" rpy="-3.060188 4.708523 -0.081638" />
            <geometry>
                <mesh filename="package://linghou_description/meshes/xarm7_with_gripper_robot_base_coll_2.dae" />
            </geometry>
        </collision>
        <collision name="LR4_R560">
            <origin xyz="0.000000 -0.000165 0.081066" rpy="-3.060188 4.708523 -0.081638" />
            <geometry>
                <mesh filename="package://linghou_description/meshes/xarm7_with_gripper_robot_base_coll_3.dae" />
            </geometry>
        </collision>
        <collision name="LR4_R560">
            <origin xyz="0.000000 -0.000165 0.081066" rpy="-3.060188 4.708523 -0.081638" />
            <geometry>
                <mesh filename="package://linghou_description/meshes/xarm7_with_gripper_robot_base_coll_4.dae" />
            </geometry>
        </collision>
        <collision name="LR4_R560">
            <origin xyz="0.000000 -0.000165 0.081066" rpy="-3.060188 4.708523 -0.081638" />
            <geometry>
                <mesh filename="package://linghou_description/meshes/xarm7_with_gripper_robot_base_coll_5.dae" />
            </geometry>
        </collision>
        <collision name="LR4_R560">
            <origin xyz="0.000000 -0.000165 0.081066" rpy="-3.060188 4.708523 -0.081638" />
            <geometry>
                <mesh filename="package://linghou_description/meshes/xarm7_with_gripper_robot_base_coll_6.dae" />
            </geometry>
        </collision>
        <collision name="LR4_R560">
            <origin xyz="0.000000 -0.000165 0.081066" rpy="-3.060188 4.708523 -0.081638" />
            <geometry>
                <mesh filename="package://linghou_description/meshes/xarm7_with_gripper_robot_base_coll_7.dae" />
            </geometry>
        </collision>
        <collision name="LR4_R560">
            <origin xyz="0.000000 -0.000165 0.081066" rpy="-3.060188 4.708523 -0.081638" />
            <geometry>
                <mesh filename="package://linghou_description/meshes/xarm7_with_gripper_robot_base_coll_8.dae" />
            </geometry>
        </collision>
        <collision name="LR4_R560">
            <origin xyz="0.000000 -0.000165 0.081066" rpy="-3.060188 4.708523 -0.081638" />
            <geometry>
                <mesh filename="package://linghou_description/meshes/xarm7_with_gripper_robot_base_coll_9.dae" />
            </geometry>
        </collision>
        <collision name="LR4_R560">
            <origin xyz="0.000000 -0.000165 0.081066" rpy="-3.060188 4.708523 -0.081638" />
            <geometry>
                <mesh filename="package://linghou_description/meshes/xarm7_with_gripper_robot_base_coll_10.dae" />
            </geometry>
        </collision>
        <collision name="LR4_R560">
            <origin xyz="0.000000 -0.000165 0.081066" rpy="-3.060188 4.708523 -0.081638" />
            <geometry>
                <mesh filename="package://linghou_description/meshes/xarm7_with_gripper_robot_base_coll_11.dae" />
            </geometry>
        </collision>
        <collision name="LR4_R560">
            <origin xyz="0.000000 -0.000165 0.081066" rpy="-3.060188 4.708523 -0.081638" />
            <geometry>
                <mesh filename="package://linghou_description/meshes/xarm7_with_gripper_robot_base_coll_12.dae" />
            </geometry>
        </collision>
        <collision name="LR4_R560">
            <origin xyz="0.000000 -0.000165 0.081066" rpy="-3.060188 4.708523 -0.081638" />
            <geometry>
                <mesh filename="package://linghou_description/meshes/xarm7_with_gripper_robot_base_coll_13.dae" />
            </geometry>
        </collision>
        <collision name="LR4_R560">
            <origin xyz="0.000000 -0.000165 0.081066" rpy="-3.060188 4.708523 -0.081638" />
            <geometry>
                <mesh filename="package://linghou_description/meshes/xarm7_with_gripper_robot_base_coll_14.dae" />
            </geometry>
        </collision>
        <collision name="LR4_R560">
            <origin xyz="0.000000 -0.000165 0.081066" rpy="-3.060188 4.708523 -0.081638" />
            <geometry>
                <mesh filename="package://linghou_description/meshes/xarm7_with_gripper_robot_base_coll_15.dae" />
            </geometry>
        </collision>
        <collision name="LR4_R560">
            <origin xyz="0.000000 -0.000165 0.081066" rpy="-3.060188 4.708523 -0.081638" />
            <geometry>
                <mesh filename="package://linghou_description/meshes/xarm7_with_gripper_robot_base_coll_16.dae" />
            </geometry>
        </collision>
        <collision name="LR4_R560">
            <origin xyz="0.000000 -0.000165 0.081066" rpy="-3.060188 4.708523 -0.081638" />
            <geometry>
                <mesh filename="package://linghou_description/meshes/xarm7_with_gripper_robot_base_coll_17.dae" />
            </geometry>
        </collision>
        <collision name="LR4_R560">
            <origin xyz="0.000000 -0.000165 0.081066" rpy="-3.060188 4.708523 -0.081638" />
            <geometry>
                <mesh filename="package://linghou_description/meshes/xarm7_with_gripper_robot_base_coll_18.dae" />
            </geometry>
        </collision>
        <collision name="LR4_R560">
            <origin xyz="0.000000 -0.000165 0.081066" rpy="-3.060188 4.708523 -0.081638" />
            <geometry>
                <mesh filename="package://linghou_description/meshes/xarm7_with_gripper_robot_base_coll_19.dae" />
            </geometry>
        </collision>
        <collision name="LR4_R560">
            <origin xyz="0.000000 -0.000165 0.081066" rpy="-3.060188 4.708523 -0.081638" />
            <geometry>
                <mesh filename="package://linghou_description/meshes/xarm7_with_gripper_robot_base_coll_20.dae" />
            </geometry>
        </collision>
        <collision name="LR4_R560">
            <origin xyz="0.000000 -0.000165 0.081066" rpy="-3.060188 4.708523 -0.081638" />
            <geometry>
                <mesh filename="package://linghou_description/meshes/xarm7_with_gripper_robot_base_coll_21.dae" />
            </geometry>
        </collision>
        <collision name="LR4_R560">
            <origin xyz="0.000000 -0.000165 0.081066" rpy="-3.060188 4.708523 -0.081638" />
            <geometry>
                <mesh filename="package://linghou_description/meshes/xarm7_with_gripper_robot_base_coll_22.dae" />
            </geometry>
        </collision>
        <collision name="LR4_R560">
            <origin xyz="0.000000 -0.000165 0.081066" rpy="-3.060188 4.708523 -0.081638" />
            <geometry>
                <mesh filename="package://linghou_description/meshes/xarm7_with_gripper_robot_base_coll_23.dae" />
            </geometry>
        </collision>
        <collision name="LR4_R560">
            <origin xyz="0.000000 -0.000165 0.081066" rpy="-3.060188 4.708523 -0.081638" />
            <geometry>
                <mesh filename="package://linghou_description/meshes/xarm7_with_gripper_robot_base_coll_24.dae" />
            </geometry>
        </collision>
        <collision name="LR4_R560">
            <origin xyz="0.000000 -0.000165 0.081066" rpy="-3.060188 4.708523 -0.081638" />
            <geometry>
                <mesh filename="package://linghou_description/meshes/xarm7_with_gripper_robot_base_coll_25.dae" />
            </geometry>
        </collision>
        <collision name="LR4_R560">
            <origin xyz="0.000000 -0.000165 0.081066" rpy="-3.060188 4.708523 -0.081638" />
            <geometry>
                <mesh filename="package://linghou_description/meshes/xarm7_with_gripper_robot_base_coll_26.dae" />
            </geometry>
        </collision>
        <collision name="LR4_R560">
            <origin xyz="0.000000 -0.000165 0.081066" rpy="-3.060188 4.708523 -0.081638" />
            <geometry>
                <mesh filename="package://linghou_description/meshes/xarm7_with_gripper_robot_base_coll_27.dae" />
            </geometry>
        </collision>
        <collision name="LR4_R560">
            <origin xyz="0.000000 -0.000165 0.081066" rpy="-3.060188 4.708523 -0.081638" />
            <geometry>
                <mesh filename="package://linghou_description/meshes/xarm7_with_gripper_robot_base_coll_28.dae" />
            </geometry>
        </collision>
        <visual name="LR4_R560_link1_visual">
            <origin xyz="0.001276 0.000366 0.100323" rpy="-0.008230 4.712374 0.008229" />
            <geometry>
                <mesh filename="package://linghou_description/meshes/xarm7_with_gripper_LR4_R560_link1_visual_vis_1.dae" />
            </geometry>
            <material name="LR4_R560_link1_visual_material">
                <color rgba="0.000000 0.000000 0.000000 1.0" />
            </material>
        </visual>
    </link>
    <joint type="revolute" name="LR4_R560_joint1">
        <axis xyz="0 0 1" />
        <parent link="robot_base" />
        <child link="LR4_R560_link2_respondable" />
        <origin xyz="-0.05145 -0.00004 0.20057" rpy="-3.14160 3.14160 3.14160" />
        <limit 
            lower="-2.967"
            upper="2.967" 
            effort="23.0"
            velocity="7.255"/>
    </joint>
    <link name="LR4_R560_link2_respondable">
        <inertial>
            <origin xyz="-0.002580 0.000034 0.090611" rpy="0 0 0"/>
            <mass value="6.0"/>
            <inertia ixx="0.04" ixy="0.0" ixz="0.0"
                    iyy="0.04" iyz="0.0"
                    izz="0.01"/>
        </inertial>
        <collision name="LR4_R560_link2_respondable">
            <origin xyz="-0.002580 0.000034 0.090611" rpy="0.001927 3.163632 3.130605" />
            <geometry>
                <mesh filename="package://linghou_description/meshes/xarm7_with_gripper_LR4_R560_link2_respondable_coll_1.dae" />
            </geometry>
        </collision>
        <collision name="LR4_R560_link2_respondable">
            <origin xyz="-0.002580 0.000034 0.090611" rpy="0.001927 3.163632 3.130605" />
            <geometry>
                <mesh filename="package://linghou_description/meshes/xarm7_with_gripper_LR4_R560_link2_respondable_coll_2.dae" />
            </geometry>
        </collision>
        <collision name="LR4_R560_link2_respondable">
            <origin xyz="-0.002580 0.000034 0.090611" rpy="0.001927 3.163632 3.130605" />
            <geometry>
                <mesh filename="package://linghou_description/meshes/xarm7_with_gripper_LR4_R560_link2_respondable_coll_3.dae" />
            </geometry>
        </collision>
        <collision name="LR4_R560_link2_respondable">
            <origin xyz="-0.002580 0.000034 0.090611" rpy="0.001927 3.163632 3.130605" />
            <geometry>
                <mesh filename="package://linghou_description/meshes/xarm7_with_gripper_LR4_R560_link2_respondable_coll_4.dae" />
            </geometry>
        </collision>
        <collision name="LR4_R560_link2_respondable">
            <origin xyz="-0.002580 0.000034 0.090611" rpy="0.001927 3.163632 3.130605" />
            <geometry>
                <mesh filename="package://linghou_description/meshes/xarm7_with_gripper_LR4_R560_link2_respondable_coll_5.dae" />
            </geometry>
        </collision>
        <collision name="LR4_R560_link2_respondable">
            <origin xyz="-0.002580 0.000034 0.090611" rpy="0.001927 3.163632 3.130605" />
            <geometry>
                <mesh filename="package://linghou_description/meshes/xarm7_with_gripper_LR4_R560_link2_respondable_coll_6.dae" />
            </geometry>
        </collision>
        <collision name="LR4_R560_link2_respondable">
            <origin xyz="-0.002580 0.000034 0.090611" rpy="0.001927 3.163632 3.130605" />
            <geometry>
                <mesh filename="package://linghou_description/meshes/xarm7_with_gripper_LR4_R560_link2_respondable_coll_7.dae" />
            </geometry>
        </collision>
        <collision name="LR4_R560_link2_respondable">
            <origin xyz="-0.002580 0.000034 0.090611" rpy="0.001927 3.163632 3.130605" />
            <geometry>
                <mesh filename="package://linghou_description/meshes/xarm7_with_gripper_LR4_R560_link2_respondable_coll_8.dae" />
            </geometry>
        </collision>
        <collision name="LR4_R560_link2_respondable">
            <origin xyz="-0.002580 0.000034 0.090611" rpy="0.001927 3.163632 3.130605" />
            <geometry>
                <mesh filename="package://linghou_description/meshes/xarm7_with_gripper_LR4_R560_link2_respondable_coll_9.dae" />
            </geometry>
        </collision>
        <collision name="LR4_R560_link2_respondable">
            <origin xyz="-0.002580 0.000034 0.090611" rpy="0.001927 3.163632 3.130605" />
            <geometry>
                <mesh filename="package://linghou_description/meshes/xarm7_with_gripper_LR4_R560_link2_respondable_coll_10.dae" />
            </geometry>
        </collision>
        <collision name="LR4_R560_link2_respondable">
            <origin xyz="-0.002580 0.000034 0.090611" rpy="0.001927 3.163632 3.130605" />
            <geometry>
                <mesh filename="package://linghou_description/meshes/xarm7_with_gripper_LR4_R560_link2_respondable_coll_11.dae" />
            </geometry>
        </collision>
        <collision name="LR4_R560_link2_respondable">
            <origin xyz="-0.002580 0.000034 0.090611" rpy="0.001927 3.163632 3.130605" />
            <geometry>
                <mesh filename="package://linghou_description/meshes/xarm7_with_gripper_LR4_R560_link2_respondable_coll_12.dae" />
            </geometry>
        </collision>
        <collision name="LR4_R560_link2_respondable">
            <origin xyz="-0.002580 0.000034 0.090611" rpy="0.001927 3.163632 3.130605" />
            <geometry>
                <mesh filename="package://linghou_description/meshes/xarm7_with_gripper_LR4_R560_link2_respondable_coll_13.dae" />
            </geometry>
        </collision>
        <collision name="LR4_R560_link2_respondable">
            <origin xyz="-0.002580 0.000034 0.090611" rpy="0.001927 3.163632 3.130605" />
            <geometry>
                <mesh filename="package://linghou_description/meshes/xarm7_with_gripper_LR4_R560_link2_respondable_coll_14.dae" />
            </geometry>
        </collision>
        <collision name="LR4_R560_link2_respondable">
            <origin xyz="-0.002580 0.000034 0.090611" rpy="0.001927 3.163632 3.130605" />
            <geometry>
                <mesh filename="package://linghou_description/meshes/xarm7_with_gripper_LR4_R560_link2_respondable_coll_15.dae" />
            </geometry>
        </collision>
        <collision name="LR4_R560_link2_respondable">
            <origin xyz="-0.002580 0.000034 0.090611" rpy="0.001927 3.163632 3.130605" />
            <geometry>
                <mesh filename="package://linghou_description/meshes/xarm7_with_gripper_LR4_R560_link2_respondable_coll_16.dae" />
            </geometry>
        </collision>
        <collision name="LR4_R560_link2_respondable">
            <origin xyz="-0.002580 0.000034 0.090611" rpy="0.001927 3.163632 3.130605" />
            <geometry>
                <mesh filename="package://linghou_description/meshes/xarm7_with_gripper_LR4_R560_link2_respondable_coll_17.dae" />
            </geometry>
        </collision>
        <collision name="LR4_R560_link2_respondable">
            <origin xyz="-0.002580 0.000034 0.090611" rpy="0.001927 3.163632 3.130605" />
            <geometry>
                <mesh filename="package://linghou_description/meshes/xarm7_with_gripper_LR4_R560_link2_respondable_coll_18.dae" />
            </geometry>
        </collision>
        <collision name="LR4_R560_link2_respondable">
            <origin xyz="-0.002580 0.000034 0.090611" rpy="0.001927 3.163632 3.130605" />
            <geometry>
                <mesh filename="package://linghou_description/meshes/xarm7_with_gripper_LR4_R560_link2_respondable_coll_19.dae" />
            </geometry>
        </collision>
        <collision name="LR4_R560_link2_respondable">
            <origin xyz="-0.002580 0.000034 0.090611" rpy="0.001927 3.163632 3.130605" />
            <geometry>
                <mesh filename="package://linghou_description/meshes/xarm7_with_gripper_LR4_R560_link2_respondable_coll_20.dae" />
            </geometry>
        </collision>
        <collision name="LR4_R560_link2_respondable">
            <origin xyz="-0.002580 0.000034 0.090611" rpy="0.001927 3.163632 3.130605" />
            <geometry>
                <mesh filename="package://linghou_description/meshes/xarm7_with_gripper_LR4_R560_link2_respondable_coll_21.dae" />
            </geometry>
        </collision>
        <collision name="LR4_R560_link2_respondable">
            <origin xyz="-0.002580 0.000034 0.090611" rpy="0.001927 3.163632 3.130605" />
            <geometry>
                <mesh filename="package://linghou_description/meshes/xarm7_with_gripper_LR4_R560_link2_respondable_coll_22.dae" />
            </geometry>
        </collision>
        <collision name="LR4_R560_link2_respondable">
            <origin xyz="-0.002580 0.000034 0.090611" rpy="0.001927 3.163632 3.130605" />
            <geometry>
                <mesh filename="package://linghou_description/meshes/xarm7_with_gripper_LR4_R560_link2_respondable_coll_23.dae" />
            </geometry>
        </collision>
        <collision name="LR4_R560_link2_respondable">
            <origin xyz="-0.002580 0.000034 0.090611" rpy="0.001927 3.163632 3.130605" />
            <geometry>
                <mesh filename="package://linghou_description/meshes/xarm7_with_gripper_LR4_R560_link2_respondable_coll_24.dae" />
            </geometry>
        </collision>
        <collision name="LR4_R560_link2_respondable">
            <origin xyz="-0.002580 0.000034 0.090611" rpy="0.001927 3.163632 3.130605" />
            <geometry>
                <mesh filename="package://linghou_description/meshes/xarm7_with_gripper_LR4_R560_link2_respondable_coll_25.dae" />
            </geometry>
        </collision>
        <collision name="LR4_R560_link2_respondable">
            <origin xyz="-0.002580 0.000034 0.090611" rpy="0.001927 3.163632 3.130605" />
            <geometry>
                <mesh filename="package://linghou_description/meshes/xarm7_with_gripper_LR4_R560_link2_respondable_coll_26.dae" />
            </geometry>
        </collision>
        <collision name="LR4_R560_link2_respondable">
            <origin xyz="-0.002580 0.000034 0.090611" rpy="0.001927 3.163632 3.130605" />
            <geometry>
                <mesh filename="package://linghou_description/meshes/xarm7_with_gripper_LR4_R560_link2_respondable_coll_27.dae" />
            </geometry>
        </collision>
        <collision name="LR4_R560_link2_respondable">
            <origin xyz="-0.002580 0.000034 0.090611" rpy="0.001927 3.163632 3.130605" />
            <geometry>
                <mesh filename="package://linghou_description/meshes/xarm7_with_gripper_LR4_R560_link2_respondable_coll_28.dae" />
            </geometry>
        </collision>
        <visual name="LR4_R560_link2_visual">
            <origin xyz="0.000077 -0.000000 0.089681" rpy="3.141592 3.141589 3.141592" />
            <geometry>
                <mesh filename="package://linghou_description/meshes/xarm7_with_gripper_LR4_R560_link2_visual_vis_1.dae" />
            </geometry>
            <material name="LR4_R560_link2_visual_material">
                <color rgba="1.000000 0.600000 0.200000 1.0" />
            </material>
        </visual>
    </link>
    <joint type="revolute" name="LR4_R560_joint2">
        <axis xyz="0 0 1" />
        <parent link="LR4_R560_link2_respondable" />
        <child link="LR4_R560_link3_respondable" />
        <origin xyz="-0.02000 -0.00000 0.14450" rpy="-1.57080 3.14159 -3.14159" />
        <limit 
            lower="-2.495"
            upper="1.518"
            effort="23.0"
            velocity="7.255"/>  <!-- 416째/s = 7.255 rad/s -->
    </joint>
    <link name="LR4_R560_link3_respondable">
        <inertial>
            <origin xyz="0.003296 0.126862 0.000113" rpy="0 0 0"/>
            <mass value="5.0"/>
            <inertia ixx="0.02" ixy="0.0" ixz="0.0"
                    iyy="0.02" iyz="0.0"
                    izz="0.03"/>
        </inertial>
        <collision name="LR4_R560_link3_respondable">
            <origin xyz="0.003296 0.126862 0.000113" rpy="1.568994 3.131033 -3.129216" />
            <geometry>
                <mesh filename="package://linghou_description/meshes/xarm7_with_gripper_LR4_R560_link3_respondable_coll_1.dae" />
            </geometry>
        </collision>
        <collision name="LR4_R560_link3_respondable">
            <origin xyz="0.003296 0.126862 0.000113" rpy="1.568994 3.131033 -3.129216" />
            <geometry>
                <mesh filename="package://linghou_description/meshes/xarm7_with_gripper_LR4_R560_link3_respondable_coll_2.dae" />
            </geometry>
        </collision>
        <collision name="LR4_R560_link3_respondable">
            <origin xyz="0.003296 0.126862 0.000113" rpy="1.568994 3.131033 -3.129216" />
            <geometry>
                <mesh filename="package://linghou_description/meshes/xarm7_with_gripper_LR4_R560_link3_respondable_coll_3.dae" />
            </geometry>
        </collision>
        <collision name="LR4_R560_link3_respondable">
            <origin xyz="0.003296 0.126862 0.000113" rpy="1.568994 3.131033 -3.129216" />
            <geometry>
                <mesh filename="package://linghou_description/meshes/xarm7_with_gripper_LR4_R560_link3_respondable_coll_4.dae" />
            </geometry>
        </collision>
        <collision name="LR4_R560_link3_respondable">
            <origin xyz="0.003296 0.126862 0.000113" rpy="1.568994 3.131033 -3.129216" />
            <geometry>
                <mesh filename="package://linghou_description/meshes/xarm7_with_gripper_LR4_R560_link3_respondable_coll_5.dae" />
            </geometry>
        </collision>
        <collision name="LR4_R560_link3_respondable">
            <origin xyz="0.003296 0.126862 0.000113" rpy="1.568994 3.131033 -3.129216" />
            <geometry>
                <mesh filename="package://linghou_description/meshes/xarm7_with_gripper_LR4_R560_link3_respondable_coll_6.dae" />
            </geometry>
        </collision>
        <collision name="LR4_R560_link3_respondable">
            <origin xyz="0.003296 0.126862 0.000113" rpy="1.568994 3.131033 -3.129216" />
            <geometry>
                <mesh filename="package://linghou_description/meshes/xarm7_with_gripper_LR4_R560_link3_respondable_coll_7.dae" />
            </geometry>
        </collision>
        <collision name="LR4_R560_link3_respondable">
            <origin xyz="0.003296 0.126862 0.000113" rpy="1.568994 3.131033 -3.129216" />
            <geometry>
                <mesh filename="package://linghou_description/meshes/xarm7_with_gripper_LR4_R560_link3_respondable_coll_8.dae" />
            </geometry>
        </collision>
        <collision name="LR4_R560_link3_respondable">
            <origin xyz="0.003296 0.126862 0.000113" rpy="1.568994 3.131033 -3.129216" />
            <geometry>
                <mesh filename="package://linghou_description/meshes/xarm7_with_gripper_LR4_R560_link3_respondable_coll_9.dae" />
            </geometry>
        </collision>
        <collision name="LR4_R560_link3_respondable">
            <origin xyz="0.003296 0.126862 0.000113" rpy="1.568994 3.131033 -3.129216" />
            <geometry>
                <mesh filename="package://linghou_description/meshes/xarm7_with_gripper_LR4_R560_link3_respondable_coll_10.dae" />
            </geometry>
        </collision>
        <collision name="LR4_R560_link3_respondable">
            <origin xyz="0.003296 0.126862 0.000113" rpy="1.568994 3.131033 -3.129216" />
            <geometry>
                <mesh filename="package://linghou_description/meshes/xarm7_with_gripper_LR4_R560_link3_respondable_coll_11.dae" />
            </geometry>
        </collision>
        <collision name="LR4_R560_link3_respondable">
            <origin xyz="0.003296 0.126862 0.000113" rpy="1.568994 3.131033 -3.129216" />
            <geometry>
                <mesh filename="package://linghou_description/meshes/xarm7_with_gripper_LR4_R560_link3_respondable_coll_12.dae" />
            </geometry>
        </collision>
        <collision name="LR4_R560_link3_respondable">
            <origin xyz="0.003296 0.126862 0.000113" rpy="1.568994 3.131033 -3.129216" />
            <geometry>
                <mesh filename="package://linghou_description/meshes/xarm7_with_gripper_LR4_R560_link3_respondable_coll_13.dae" />
            </geometry>
        </collision>
        <collision name="LR4_R560_link3_respondable">
            <origin xyz="0.003296 0.126862 0.000113" rpy="1.568994 3.131033 -3.129216" />
            <geometry>
                <mesh filename="package://linghou_description/meshes/xarm7_with_gripper_LR4_R560_link3_respondable_coll_14.dae" />
            </geometry>
        </collision>
        <collision name="LR4_R560_link3_respondable">
            <origin xyz="0.003296 0.126862 0.000113" rpy="1.568994 3.131033 -3.129216" />
            <geometry>
                <mesh filename="package://linghou_description/meshes/xarm7_with_gripper_LR4_R560_link3_respondable_coll_15.dae" />
            </geometry>
        </collision>
        <visual name="LR4_R560_link3_visual">
            <origin xyz="0.004963 0.126339 -0.000129" rpy="1.571017 3.153163 3.127580" />
            <geometry>
                <mesh filename="package://linghou_description/meshes/xarm7_with_gripper_LR4_R560_link3_visual_vis_1.dae" />
            </geometry>
            <material name="LR4_R560_link3_visual_material">
                <color rgba="1.000000 0.600000 0.200000 1.0" />
            </material>
        </visual>
    </link>
    <joint type="revolute" name="LR4_R560_joint3">
        <axis xyz="0 0 1" />
        <parent link="LR4_R560_link3_respondable" />
        <child link="LR4_R560_link4_respondable" />
        <origin xyz="0.00000 0.26000 0.00000" rpy="-3.14159 3.14160 -0.00000" />
        <limit 
            lower="-3.577"
            upper="0.925"
            effort="20.7"
            velocity="8.062"/>  <!-- 462째/s = 8.062 rad/s -->
    </joint>
    <link name="LR4_R560_link4_respondable">
        <inertial>
            <origin xyz="0.013688 0.002571 0.002943" rpy="0 0 0"/>
            <mass value="2.0"/>
            <inertia ixx="0.008" ixy="0.0" ixz="0.0"
                    iyy="0.008" iyz="0.0"
                    izz="0.004"/>
        </inertial>
        <collision name="LR4_R560_link4_respondable">
            <origin xyz="0.013688 0.002571 0.002943" rpy="2.569508 1.614796 2.498315" />
            <geometry>
                <mesh filename="package://linghou_description/meshes/xarm7_with_gripper_LR4_R560_link4_respondable_coll_1.dae" />
            </geometry>
        </collision>
        <collision name="LR4_R560_link4_respondable">
            <origin xyz="0.013688 0.002571 0.002943" rpy="2.569508 1.614796 2.498315" />
            <geometry>
                <mesh filename="package://linghou_description/meshes/xarm7_with_gripper_LR4_R560_link4_respondable_coll_2.dae" />
            </geometry>
        </collision>
        <collision name="LR4_R560_link4_respondable">
            <origin xyz="0.013688 0.002571 0.002943" rpy="2.569508 1.614796 2.498315" />
            <geometry>
                <mesh filename="package://linghou_description/meshes/xarm7_with_gripper_LR4_R560_link4_respondable_coll_3.dae" />
            </geometry>
        </collision>
        <collision name="LR4_R560_link4_respondable">
            <origin xyz="0.013688 0.002571 0.002943" rpy="2.569508 1.614796 2.498315" />
            <geometry>
                <mesh filename="package://linghou_description/meshes/xarm7_with_gripper_LR4_R560_link4_respondable_coll_4.dae" />
            </geometry>
        </collision>
        <collision name="LR4_R560_link4_respondable">
            <origin xyz="0.013688 0.002571 0.002943" rpy="2.569508 1.614796 2.498315" />
            <geometry>
                <mesh filename="package://linghou_description/meshes/xarm7_with_gripper_LR4_R560_link4_respondable_coll_5.dae" />
            </geometry>
        </collision>
        <collision name="LR4_R560_link4_respondable">
            <origin xyz="0.013688 0.002571 0.002943" rpy="2.569508 1.614796 2.498315" />
            <geometry>
                <mesh filename="package://linghou_description/meshes/xarm7_with_gripper_LR4_R560_link4_respondable_coll_6.dae" />
            </geometry>
        </collision>
        <collision name="LR4_R560_link4_respondable">
            <origin xyz="0.013688 0.002571 0.002943" rpy="2.569508 1.614796 2.498315" />
            <geometry>
                <mesh filename="package://linghou_description/meshes/xarm7_with_gripper_LR4_R560_link4_respondable_coll_7.dae" />
            </geometry>
        </collision>
        <collision name="LR4_R560_link4_respondable">
            <origin xyz="0.013688 0.002571 0.002943" rpy="2.569508 1.614796 2.498315" />
            <geometry>
                <mesh filename="package://linghou_description/meshes/xarm7_with_gripper_LR4_R560_link4_respondable_coll_8.dae" />
            </geometry>
        </collision>
        <collision name="LR4_R560_link4_respondable">
            <origin xyz="0.013688 0.002571 0.002943" rpy="2.569508 1.614796 2.498315" />
            <geometry>
                <mesh filename="package://linghou_description/meshes/xarm7_with_gripper_LR4_R560_link4_respondable_coll_9.dae" />
            </geometry>
        </collision>
        <collision name="LR4_R560_link4_respondable">
            <origin xyz="0.013688 0.002571 0.002943" rpy="2.569508 1.614796 2.498315" />
            <geometry>
                <mesh filename="package://linghou_description/meshes/xarm7_with_gripper_LR4_R560_link4_respondable_coll_10.dae" />
            </geometry>
        </collision>
        <collision name="LR4_R560_link4_respondable">
            <origin xyz="0.013688 0.002571 0.002943" rpy="2.569508 1.614796 2.498315" />
            <geometry>
                <mesh filename="package://linghou_description/meshes/xarm7_with_gripper_LR4_R560_link4_respondable_coll_11.dae" />
            </geometry>
        </collision>
        <collision name="LR4_R560_link4_respondable">
            <origin xyz="0.013688 0.002571 0.002943" rpy="2.569508 1.614796 2.498315" />
            <geometry>
                <mesh filename="package://linghou_description/meshes/xarm7_with_gripper_LR4_R560_link4_respondable_coll_12.dae" />
            </geometry>
        </collision>
        <visual name="LR4_R560_link4_visual">
            <origin xyz="0.011481 0.000933 0.004500" rpy="-1.546407 1.570815 -1.537021" />
            <geometry>
                <mesh filename="package://linghou_description/meshes/xarm7_with_gripper_LR4_R560_link4_visual_vis_1.dae" />
            </geometry>
            <material name="LR4_R560_link4_visual_material">
                <color rgba="1.000000 0.600000 0.200000 1.0" />
            </material>
        </visual>
    </link>
    <joint type="revolute" name="LR4_R560_joint4">
        <axis xyz="0 0 1" />
        <parent link="LR4_R560_link4_respondable" />
        <child link="LR4_R560_link5_respondable" />
        <origin xyz="0.09018 -0.01915 0.00000" rpy="-1.57079 3.14160 -1.56141" />
        <limit 
            lower="-3.490"
            upper="3.490" 
            effort="16.3"
            velocity="8.727"/>  <!-- 500째/s = 8.727 rad/s -->
    </joint>
    <link name="LR4_R560_link5_respondable">
        <inertial>
            <origin xyz="-0.006137 -0.000332 0.112352" rpy="0 0 0"/>
            <mass value="1.5"/>
            <inertia ixx="0.006" ixy="0.0" ixz="0.0"
                    iyy="0.006" iyz="0.0"
                    izz="0.003"/>
        </inertial>
        <collision name="LR4_R560_link5_respondable">
            <origin xyz="-0.006137 -0.000332 0.112352" rpy="-0.002565 3.173645 -3.075990" />
            <geometry>
                <mesh filename="package://linghou_description/meshes/xarm7_with_gripper_LR4_R560_link5_respondable_coll_1.dae" />
            </geometry>
        </collision>
        <collision name="LR4_R560_link5_respondable">
            <origin xyz="-0.006137 -0.000332 0.112352" rpy="-0.002565 3.173645 -3.075990" />
            <geometry>
                <mesh filename="package://linghou_description/meshes/xarm7_with_gripper_LR4_R560_link5_respondable_coll_2.dae" />
            </geometry>
        </collision>
        <collision name="LR4_R560_link5_respondable">
            <origin xyz="-0.006137 -0.000332 0.112352" rpy="-0.002565 3.173645 -3.075990" />
            <geometry>
                <mesh filename="package://linghou_description/meshes/xarm7_with_gripper_LR4_R560_link5_respondable_coll_3.dae" />
            </geometry>
        </collision>
        <collision name="LR4_R560_link5_respondable">
            <origin xyz="-0.006137 -0.000332 0.112352" rpy="-0.002565 3.173645 -3.075990" />
            <geometry>
                <mesh filename="package://linghou_description/meshes/xarm7_with_gripper_LR4_R560_link5_respondable_coll_4.dae" />
            </geometry>
        </collision>
        <collision name="LR4_R560_link5_respondable">
            <origin xyz="-0.006137 -0.000332 0.112352" rpy="-0.002565 3.173645 -3.075990" />
            <geometry>
                <mesh filename="package://linghou_description/meshes/xarm7_with_gripper_LR4_R560_link5_respondable_coll_5.dae" />
            </geometry>
        </collision>
        <collision name="LR4_R560_link5_respondable">
            <origin xyz="-0.006137 -0.000332 0.112352" rpy="-0.002565 3.173645 -3.075990" />
            <geometry>
                <mesh filename="package://linghou_description/meshes/xarm7_with_gripper_LR4_R560_link5_respondable_coll_6.dae" />
            </geometry>
        </collision>
        <collision name="LR4_R560_link5_respondable">
            <origin xyz="-0.006137 -0.000332 0.112352" rpy="-0.002565 3.173645 -3.075990" />
            <geometry>
                <mesh filename="package://linghou_description/meshes/xarm7_with_gripper_LR4_R560_link5_respondable_coll_7.dae" />
            </geometry>
        </collision>
        <collision name="LR4_R560_link5_respondable">
            <origin xyz="-0.006137 -0.000332 0.112352" rpy="-0.002565 3.173645 -3.075990" />
            <geometry>
                <mesh filename="package://linghou_description/meshes/xarm7_with_gripper_LR4_R560_link5_respondable_coll_8.dae" />
            </geometry>
        </collision>
        <collision name="LR4_R560_link5_respondable">
            <origin xyz="-0.006137 -0.000332 0.112352" rpy="-0.002565 3.173645 -3.075990" />
            <geometry>
                <mesh filename="package://linghou_description/meshes/xarm7_with_gripper_LR4_R560_link5_respondable_coll_9.dae" />
            </geometry>
        </collision>
        <collision name="LR4_R560_link5_respondable">
            <origin xyz="-0.006137 -0.000332 0.112352" rpy="-0.002565 3.173645 -3.075990" />
            <geometry>
                <mesh filename="package://linghou_description/meshes/xarm7_with_gripper_LR4_R560_link5_respondable_coll_10.dae" />
            </geometry>
        </collision>
        <collision name="LR4_R560_link5_respondable">
            <origin xyz="-0.006137 -0.000332 0.112352" rpy="-0.002565 3.173645 -3.075990" />
            <geometry>
                <mesh filename="package://linghou_description/meshes/xarm7_with_gripper_LR4_R560_link5_respondable_coll_11.dae" />
            </geometry>
        </collision>
        <collision name="LR4_R560_link5_respondable">
            <origin xyz="-0.006137 -0.000332 0.112352" rpy="-0.002565 3.173645 -3.075990" />
            <geometry>
                <mesh filename="package://linghou_description/meshes/xarm7_with_gripper_LR4_R560_link5_respondable_coll_12.dae" />
            </geometry>
        </collision>
        <collision name="LR4_R560_link5_respondable">
            <origin xyz="-0.006137 -0.000332 0.112352" rpy="-0.002565 3.173645 -3.075990" />
            <geometry>
                <mesh filename="package://linghou_description/meshes/xarm7_with_gripper_LR4_R560_link5_respondable_coll_13.dae" />
            </geometry>
        </collision>
        <collision name="LR4_R560_link5_respondable">
            <origin xyz="-0.006137 -0.000332 0.112352" rpy="-0.002565 3.173645 -3.075990" />
            <geometry>
                <mesh filename="package://linghou_description/meshes/xarm7_with_gripper_LR4_R560_link5_respondable_coll_14.dae" />
            </geometry>
        </collision>
        <visual name="LR4_R560_link5_visual">
            <origin xyz="-0.006347 -0.000195 0.112127" rpy="3.138413 3.183540 -3.081190" />
            <geometry>
                <mesh filename="package://linghou_description/meshes/xarm7_with_gripper_LR4_R560_link5_visual_vis_1.dae" />
            </geometry>
            <material name="LR4_R560_link5_visual_material">
                <color rgba="1.000000 0.600000 0.200000 1.0" />
            </material>
        </visual>
    </link>
    <joint type="revolute" name="LR4_R560_joint5">
        <axis xyz="0 0 1" />
        <parent link="LR4_R560_link5_respondable" />
        <child link="LR4_R560_link6_respondable" />
        <origin xyz="0.00000 0.00000 0.19000" rpy="-1.57047 1.58018 -3.14127" />
        <limit 
            lower="-2.181"
            upper="2.181" 
            effort="17.1"
            velocity="9.774"/>  <!-- 560째/s = 9.774 rad/s -->
    </joint>
    <link name="LR4_R560_link6_respondable">
        <inertial>
            <origin xyz="-0.014049 0.000067 -0.000817" rpy="0 0 0"/>
            <mass value="1.2"/>
            <inertia ixx="0.005" ixy="0.0" ixz="0.0"
                    iyy="0.005" iyz="0.0"
                    izz="0.002"/>
        </inertial>
        <collision name="LR4_R560_link6_respondable">
            <origin xyz="-0.014049 0.000067 -0.000817" rpy="1.840752 1.577596 1.827882" />
            <geometry>
                <mesh filename="package://linghou_description/meshes/xarm7_with_gripper_LR4_R560_link6_respondable_coll_1.dae" />
            </geometry>
        </collision>
        <collision name="LR4_R560_link6_respondable">
            <origin xyz="-0.014049 0.000067 -0.000817" rpy="1.840752 1.577596 1.827882" />
            <geometry>
                <mesh filename="package://linghou_description/meshes/xarm7_with_gripper_LR4_R560_link6_respondable_coll_2.dae" />
            </geometry>
        </collision>
        <collision name="LR4_R560_link6_respondable">
            <origin xyz="-0.014049 0.000067 -0.000817" rpy="1.840752 1.577596 1.827882" />
            <geometry>
                <mesh filename="package://linghou_description/meshes/xarm7_with_gripper_LR4_R560_link6_respondable_coll_3.dae" />
            </geometry>
        </collision>
        <collision name="LR4_R560_link6_respondable">
            <origin xyz="-0.014049 0.000067 -0.000817" rpy="1.840752 1.577596 1.827882" />
            <geometry>
                <mesh filename="package://linghou_description/meshes/xarm7_with_gripper_LR4_R560_link6_respondable_coll_4.dae" />
            </geometry>
        </collision>
        <collision name="LR4_R560_link6_respondable">
            <origin xyz="-0.014049 0.000067 -0.000817" rpy="1.840752 1.577596 1.827882" />
            <geometry>
                <mesh filename="package://linghou_description/meshes/xarm7_with_gripper_LR4_R560_link6_respondable_coll_5.dae" />
            </geometry>
        </collision>
        <collision name="LR4_R560_link6_respondable">
            <origin xyz="-0.014049 0.000067 -0.000817" rpy="1.840752 1.577596 1.827882" />
            <geometry>
                <mesh filename="package://linghou_description/meshes/xarm7_with_gripper_LR4_R560_link6_respondable_coll_6.dae" />
            </geometry>
        </collision>
        <collision name="LR4_R560_link6_respondable">
            <origin xyz="-0.014049 0.000067 -0.000817" rpy="1.840752 1.577596 1.827882" />
            <geometry>
                <mesh filename="package://linghou_description/meshes/xarm7_with_gripper_LR4_R560_link6_respondable_coll_7.dae" />
            </geometry>
        </collision>
        <collision name="LR4_R560_link6_respondable">
            <origin xyz="-0.014049 0.000067 -0.000817" rpy="1.840752 1.577596 1.827882" />
            <geometry>
                <mesh filename="package://linghou_description/meshes/xarm7_with_gripper_LR4_R560_link6_respondable_coll_8.dae" />
            </geometry>
        </collision>
        <collision name="LR4_R560_link6_respondable">
            <origin xyz="-0.014049 0.000067 -0.000817" rpy="1.840752 1.577596 1.827882" />
            <geometry>
                <mesh filename="package://linghou_description/meshes/xarm7_with_gripper_LR4_R560_link6_respondable_coll_9.dae" />
            </geometry>
        </collision>
        <collision name="LR4_R560_link6_respondable">
            <origin xyz="-0.014049 0.000067 -0.000817" rpy="1.840752 1.577596 1.827882" />
            <geometry>
                <mesh filename="package://linghou_description/meshes/xarm7_with_gripper_LR4_R560_link6_respondable_coll_10.dae" />
            </geometry>
        </collision>
        <collision name="LR4_R560_link6_respondable">
            <origin xyz="-0.014049 0.000067 -0.000817" rpy="1.840752 1.577596 1.827882" />
            <geometry>
                <mesh filename="package://linghou_description/meshes/xarm7_with_gripper_LR4_R560_link6_respondable_coll_11.dae" />
            </geometry>
        </collision>
        <collision name="LR4_R560_link6_respondable">
            <origin xyz="-0.014049 0.000067 -0.000817" rpy="1.840752 1.577596 1.827882" />
            <geometry>
                <mesh filename="package://linghou_description/meshes/xarm7_with_gripper_LR4_R560_link6_respondable_coll_12.dae" />
            </geometry>
        </collision>
        <collision name="LR4_R560_link6_respondable">
            <origin xyz="-0.014049 0.000067 -0.000817" rpy="1.840752 1.577596 1.827882" />
            <geometry>
                <mesh filename="package://linghou_description/meshes/xarm7_with_gripper_LR4_R560_link6_respondable_coll_13.dae" />
            </geometry>
        </collision>
        <collision name="LR4_R560_link6_respondable">
            <origin xyz="-0.014049 0.000067 -0.000817" rpy="1.840752 1.577596 1.827882" />
            <geometry>
                <mesh filename="package://linghou_description/meshes/xarm7_with_gripper_LR4_R560_link6_respondable_coll_14.dae" />
            </geometry>
        </collision>
        <collision name="LR4_R560_link6_respondable">
            <origin xyz="-0.014049 0.000067 -0.000817" rpy="1.840752 1.577596 1.827882" />
            <geometry>
                <mesh filename="package://linghou_description/meshes/xarm7_with_gripper_LR4_R560_link6_respondable_coll_15.dae" />
            </geometry>
        </collision>
        <collision name="LR4_R560_link6_respondable">
            <origin xyz="-0.014049 0.000067 -0.000817" rpy="1.840752 1.577596 1.827882" />
            <geometry>
                <mesh filename="package://linghou_description/meshes/xarm7_with_gripper_LR4_R560_link6_respondable_coll_16.dae" />
            </geometry>
        </collision>
        <collision name="LR4_R560_link6_respondable">
            <origin xyz="-0.014049 0.000067 -0.000817" rpy="1.840752 1.577596 1.827882" />
            <geometry>
                <mesh filename="package://linghou_description/meshes/xarm7_with_gripper_LR4_R560_link6_respondable_coll_17.dae" />
            </geometry>
        </collision>
        <collision name="LR4_R560_link6_respondable">
            <origin xyz="-0.014049 0.000067 -0.000817" rpy="1.840752 1.577596 1.827882" />
            <geometry>
                <mesh filename="package://linghou_description/meshes/xarm7_with_gripper_LR4_R560_link6_respondable_coll_18.dae" />
            </geometry>
        </collision>
        <collision name="LR4_R560_link6_respondable">
            <origin xyz="-0.014049 0.000067 -0.000817" rpy="1.840752 1.577596 1.827882" />
            <geometry>
                <mesh filename="package://linghou_description/meshes/xarm7_with_gripper_LR4_R560_link6_respondable_coll_19.dae" />
            </geometry>
        </collision>
        <collision name="LR4_R560_link6_respondable">
            <origin xyz="-0.014049 0.000067 -0.000817" rpy="1.840752 1.577596 1.827882" />
            <geometry>
                <mesh filename="package://linghou_description/meshes/xarm7_with_gripper_LR4_R560_link6_respondable_coll_20.dae" />
            </geometry>
        </collision>
        <collision name="LR4_R560_link6_respondable">
            <origin xyz="-0.014049 0.000067 -0.000817" rpy="1.840752 1.577596 1.827882" />
            <geometry>
                <mesh filename="package://linghou_description/meshes/xarm7_with_gripper_LR4_R560_link6_respondable_coll_21.dae" />
            </geometry>
        </collision>
        <collision name="LR4_R560_link6_respondable">
            <origin xyz="-0.014049 0.000067 -0.000817" rpy="1.840752 1.577596 1.827882" />
            <geometry>
                <mesh filename="package://linghou_description/meshes/xarm7_with_gripper_LR4_R560_link6_respondable_coll_22.dae" />
            </geometry>
        </collision>
        <collision name="LR4_R560_link6_respondable">
            <origin xyz="-0.014049 0.000067 -0.000817" rpy="1.840752 1.577596 1.827882" />
            <geometry>
                <mesh filename="package://linghou_description/meshes/xarm7_with_gripper_LR4_R560_link6_respondable_coll_23.dae" />
            </geometry>
        </collision>
        <collision name="LR4_R560_link6_respondable">
            <origin xyz="-0.014049 0.000067 -0.000817" rpy="1.840752 1.577596 1.827882" />
            <geometry>
                <mesh filename="package://linghou_description/meshes/xarm7_with_gripper_LR4_R560_link6_respondable_coll_24.dae" />
            </geometry>
        </collision>
        <collision name="LR4_R560_link6_respondable">
            <origin xyz="-0.014049 0.000067 -0.000817" rpy="1.840752 1.577596 1.827882" />
            <geometry>
                <mesh filename="package://linghou_description/meshes/xarm7_with_gripper_LR4_R560_link6_respondable_coll_25.dae" />
            </geometry>
        </collision>
        <collision name="LR4_R560_link6_respondable">
            <origin xyz="-0.014049 0.000067 -0.000817" rpy="1.840752 1.577596 1.827882" />
            <geometry>
                <mesh filename="package://linghou_description/meshes/xarm7_with_gripper_LR4_R560_link6_respondable_coll_26.dae" />
            </geometry>
        </collision>
        <collision name="LR4_R560_link6_respondable">
            <origin xyz="-0.014049 0.000067 -0.000817" rpy="1.840752 1.577596 1.827882" />
            <geometry>
                <mesh filename="package://linghou_description/meshes/xarm7_with_gripper_LR4_R560_link6_respondable_coll_27.dae" />
            </geometry>
        </collision>
        <collision name="LR4_R560_link6_respondable">
            <origin xyz="-0.014049 0.000067 -0.000817" rpy="1.840752 1.577596 1.827882" />
            <geometry>
                <mesh filename="package://linghou_description/meshes/xarm7_with_gripper_LR4_R560_link6_respondable_coll_28.dae" />
            </geometry>
        </collision>
        <collision name="LR4_R560_link6_respondable">
            <origin xyz="-0.014049 0.000067 -0.000817" rpy="1.840752 1.577596 1.827882" />
            <geometry>
                <mesh filename="package://linghou_description/meshes/xarm7_with_gripper_LR4_R560_link6_respondable_coll_29.dae" />
            </geometry>
        </collision>
        <collision name="LR4_R560_link6_respondable">
            <origin xyz="-0.014049 0.000067 -0.000817" rpy="1.840752 1.577596 1.827882" />
            <geometry>
                <mesh filename="package://linghou_description/meshes/xarm7_with_gripper_LR4_R560_link6_respondable_coll_30.dae" />
            </geometry>
        </collision>
        <collision name="LR4_R560_link6_respondable">
            <origin xyz="-0.014049 0.000067 -0.000817" rpy="1.840752 1.577596 1.827882" />
            <geometry>
                <mesh filename="package://linghou_description/meshes/xarm7_with_gripper_LR4_R560_link6_respondable_coll_31.dae" />
            </geometry>
        </collision>
        <collision name="LR4_R560_link6_respondable">
            <origin xyz="-0.014049 0.000067 -0.000817" rpy="1.840752 1.577596 1.827882" />
            <geometry>
                <mesh filename="package://linghou_description/meshes/xarm7_with_gripper_LR4_R560_link6_respondable_coll_32.dae" />
            </geometry>
        </collision>
        <collision name="LR4_R560_link6_respondable">
            <origin xyz="-0.014049 0.000067 -0.000817" rpy="1.840752 1.577596 1.827882" />
            <geometry>
                <mesh filename="package://linghou_description/meshes/xarm7_with_gripper_LR4_R560_link6_respondable_coll_33.dae" />
            </geometry>
        </collision>
        <collision name="LR4_R560_link6_respondable">
            <origin xyz="-0.014049 0.000067 -0.000817" rpy="1.840752 1.577596 1.827882" />
            <geometry>
                <mesh filename="package://linghou_description/meshes/xarm7_with_gripper_LR4_R560_link6_respondable_coll_34.dae" />
            </geometry>
        </collision>
        <collision name="LR4_R560_link6_respondable">
            <origin xyz="-0.014049 0.000067 -0.000817" rpy="1.840752 1.577596 1.827882" />
            <geometry>
                <mesh filename="package://linghou_description/meshes/xarm7_with_gripper_LR4_R560_link6_respondable_coll_35.dae" />
            </geometry>
        </collision>
        <collision name="LR4_R560_link6_respondable">
            <origin xyz="-0.014049 0.000067 -0.000817" rpy="1.840752 1.577596 1.827882" />
            <geometry>
                <mesh filename="package://linghou_description/meshes/xarm7_with_gripper_LR4_R560_link6_respondable_coll_36.dae" />
            </geometry>
        </collision>
        <collision name="LR4_R560_link6_respondable">
            <origin xyz="-0.014049 0.000067 -0.000817" rpy="1.840752 1.577596 1.827882" />
            <geometry>
                <mesh filename="package://linghou_description/meshes/xarm7_with_gripper_LR4_R560_link6_respondable_coll_37.dae" />
            </geometry>
        </collision>
        <collision name="LR4_R560_link6_respondable">
            <origin xyz="-0.014049 0.000067 -0.000817" rpy="1.840752 1.577596 1.827882" />
            <geometry>
                <mesh filename="package://linghou_description/meshes/xarm7_with_gripper_LR4_R560_link6_respondable_coll_38.dae" />
            </geometry>
        </collision>
        <visual name="LR4_R560_link6_visual">
            <origin xyz="-0.014749 0.000140 -0.001551" rpy="1.630457 1.570892 1.621053" />
            <geometry>
                <mesh filename="package://linghou_description/meshes/xarm7_with_gripper_LR4_R560_link6_visual_vis_1.dae" />
            </geometry>
            <material name="LR4_R560_link6_visual_material">
                <color rgba="1.000000 0.600000 0.200000 1.0" />
            </material>
        </visual>
    </link>
    <joint type="revolute" name="LR4_R560_joint6">
        <axis xyz="0 0 1" />
        <parent link="LR4_R560_link6_respondable" />
        <child link="LR4_R560_link7_respondable" />
        <origin xyz="-0.06700 0.00063 -0.00000" rpy="1.57079 3.14159 -1.58019" />
        <limit 
            lower="-6.283"
            upper="6.283" 
            effort="13.0"
            velocity="12.915"/> <!-- 740째/s = 12.915 rad/s -->
    </joint>
    <link name="LR4_R560_link7_respondable">
        <inertial>
            <origin xyz="-0.000154 0.000131 0.005256" rpy="0 0 0"/>
            <mass value="0.3"/>
            <inertia ixx="0.0003" ixy="0.0" ixz="0.0"
                    iyy="0.0003" iyz="0.0"
                    izz="0.00015"/>
        </inertial>
        <collision name="LR4_R560_link7_respondable">
            <origin xyz="-0.000154 0.000131 0.005256" rpy="-2.316304 1.571449 1.567710" />
            <geometry>
                <mesh filename="package://linghou_description/meshes/xarm7_with_gripper_LR4_R560_link7_respondable_coll_1.dae" />
            </geometry>
        </collision>
        <collision name="LR4_R560_link7_respondable">
            <origin xyz="-0.000154 0.000131 0.005256" rpy="-2.316304 1.571449 1.567710" />
            <geometry>
                <mesh filename="package://linghou_description/meshes/xarm7_with_gripper_LR4_R560_link7_respondable_coll_2.dae" />
            </geometry>
        </collision>
        <collision name="LR4_R560_link7_respondable">
            <origin xyz="-0.000154 0.000131 0.005256" rpy="-2.316304 1.571449 1.567710" />
            <geometry>
                <mesh filename="package://linghou_description/meshes/xarm7_with_gripper_LR4_R560_link7_respondable_coll_3.dae" />
            </geometry>
        </collision>
        <collision name="LR4_R560_link7_respondable">
            <origin xyz="-0.000154 0.000131 0.005256" rpy="-2.316304 1.571449 1.567710" />
            <geometry>
                <mesh filename="package://linghou_description/meshes/xarm7_with_gripper_LR4_R560_link7_respondable_coll_4.dae" />
            </geometry>
        </collision>
        <collision name="LR4_R560_link7_respondable">
            <origin xyz="-0.000154 0.000131 0.005256" rpy="-2.316304 1.571449 1.567710" />
            <geometry>
                <mesh filename="package://linghou_description/meshes/xarm7_with_gripper_LR4_R560_link7_respondable_coll_5.dae" />
            </geometry>
        </collision>
        <collision name="LR4_R560_link7_respondable">
            <origin xyz="-0.000154 0.000131 0.005256" rpy="-2.316304 1.571449 1.567710" />
            <geometry>
                <mesh filename="package://linghou_description/meshes/xarm7_with_gripper_LR4_R560_link7_respondable_coll_6.dae" />
            </geometry>
        </collision>
        <collision name="LR4_R560_link7_respondable">
            <origin xyz="-0.000154 0.000131 0.005256" rpy="-2.316304 1.571449 1.567710" />
            <geometry>
                <mesh filename="package://linghou_description/meshes/xarm7_with_gripper_LR4_R560_link7_respondable_coll_7.dae" />
            </geometry>
        </collision>
        <collision name="LR4_R560_link7_respondable">
            <origin xyz="-0.000154 0.000131 0.005256" rpy="-2.316304 1.571449 1.567710" />
            <geometry>
                <mesh filename="package://linghou_description/meshes/xarm7_with_gripper_LR4_R560_link7_respondable_coll_8.dae" />
            </geometry>
        </collision>
        <collision name="LR4_R560_link7_respondable">
            <origin xyz="-0.000154 0.000131 0.005256" rpy="-2.316304 1.571449 1.567710" />
            <geometry>
                <mesh filename="package://linghou_description/meshes/xarm7_with_gripper_LR4_R560_link7_respondable_coll_9.dae" />
            </geometry>
        </collision>
        <collision name="LR4_R560_link7_respondable">
            <origin xyz="-0.000154 0.000131 0.005256" rpy="-2.316304 1.571449 1.567710" />
            <geometry>
                <mesh filename="package://linghou_description/meshes/xarm7_with_gripper_LR4_R560_link7_respondable_coll_10.dae" />
            </geometry>
        </collision>
        <collision name="LR4_R560_link7_respondable">
            <origin xyz="-0.000154 0.000131 0.005256" rpy="-2.316304 1.571449 1.567710" />
            <geometry>
                <mesh filename="package://linghou_description/meshes/xarm7_with_gripper_LR4_R560_link7_respondable_coll_11.dae" />
            </geometry>
        </collision>
        <collision name="LR4_R560_link7_respondable">
            <origin xyz="-0.000154 0.000131 0.005256" rpy="-2.316304 1.571449 1.567710" />
            <geometry>
                <mesh filename="package://linghou_description/meshes/xarm7_with_gripper_LR4_R560_link7_respondable_coll_12.dae" />
            </geometry>
        </collision>
        <collision name="LR4_R560_link7_respondable">
            <origin xyz="-0.000154 0.000131 0.005256" rpy="-2.316304 1.571449 1.567710" />
            <geometry>
                <mesh filename="package://linghou_description/meshes/xarm7_with_gripper_LR4_R560_link7_respondable_coll_13.dae" />
            </geometry>
        </collision>
        <collision name="LR4_R560_link7_respondable">
            <origin xyz="-0.000154 0.000131 0.005256" rpy="-2.316304 1.571449 1.567710" />
            <geometry>
                <mesh filename="package://linghou_description/meshes/xarm7_with_gripper_LR4_R560_link7_respondable_coll_14.dae" />
            </geometry>
        </collision>
        <collision name="LR4_R560_link7_respondable">
            <origin xyz="-0.000154 0.000131 0.005256" rpy="-2.316304 1.571449 1.567710" />
            <geometry>
                <mesh filename="package://linghou_description/meshes/xarm7_with_gripper_LR4_R560_link7_respondable_coll_15.dae" />
            </geometry>
        </collision>
        <collision name="LR4_R560_link7_respondable">
            <origin xyz="-0.000154 0.000131 0.005256" rpy="-2.316304 1.571449 1.567710" />
            <geometry>
                <mesh filename="package://linghou_description/meshes/xarm7_with_gripper_LR4_R560_link7_respondable_coll_16.dae" />
            </geometry>
        </collision>
        <collision name="LR4_R560_link7_respondable">
            <origin xyz="-0.000154 0.000131 0.005256" rpy="-2.316304 1.571449 1.567710" />
            <geometry>
                <mesh filename="package://linghou_description/meshes/xarm7_with_gripper_LR4_R560_link7_respondable_coll_17.dae" />
            </geometry>
        </collision>
        <collision name="LR4_R560_link7_respondable">
            <origin xyz="-0.000154 0.000131 0.005256" rpy="-2.316304 1.571449 1.567710" />
            <geometry>
                <mesh filename="package://linghou_description/meshes/xarm7_with_gripper_LR4_R560_link7_respondable_coll_18.dae" />
            </geometry>
        </collision>
        <collision name="LR4_R560_link7_respondable">
            <origin xyz="-0.000154 0.000131 0.005256" rpy="-2.316304 1.571449 1.567710" />
            <geometry>
                <mesh filename="package://linghou_description/meshes/xarm7_with_gripper_LR4_R560_link7_respondable_coll_19.dae" />
            </geometry>
        </collision>
        <collision name="LR4_R560_link7_respondable">
            <origin xyz="-0.000154 0.000131 0.005256" rpy="-2.316304 1.571449 1.567710" />
            <geometry>
                <mesh filename="package://linghou_description/meshes/xarm7_with_gripper_LR4_R560_link7_respondable_coll_20.dae" />
            </geometry>
        </collision>
        <collision name="LR4_R560_link7_respondable">
            <origin xyz="-0.000154 0.000131 0.005256" rpy="-2.316304 1.571449 1.567710" />
            <geometry>
                <mesh filename="package://linghou_description/meshes/xarm7_with_gripper_LR4_R560_link7_respondable_coll_21.dae" />
            </geometry>
        </collision>
        <collision name="LR4_R560_link7_respondable">
            <origin xyz="-0.000154 0.000131 0.005256" rpy="-2.316304 1.571449 1.567710" />
            <geometry>
                <mesh filename="package://linghou_description/meshes/xarm7_with_gripper_LR4_R560_link7_respondable_coll_22.dae" />
            </geometry>
        </collision>
        <collision name="LR4_R560_link7_respondable">
            <origin xyz="-0.000154 0.000131 0.005256" rpy="-2.316304 1.571449 1.567710" />
            <geometry>
                <mesh filename="package://linghou_description/meshes/xarm7_with_gripper_LR4_R560_link7_respondable_coll_23.dae" />
            </geometry>
        </collision>
        <collision name="LR4_R560_link7_respondable">
            <origin xyz="-0.000154 0.000131 0.005256" rpy="-2.316304 1.571449 1.567710" />
            <geometry>
                <mesh filename="package://linghou_description/meshes/xarm7_with_gripper_LR4_R560_link7_respondable_coll_24.dae" />
            </geometry>
        </collision>
        <collision name="LR4_R560_link7_respondable">
            <origin xyz="-0.000154 0.000131 0.005256" rpy="-2.316304 1.571449 1.567710" />
            <geometry>
                <mesh filename="package://linghou_description/meshes/xarm7_with_gripper_LR4_R560_link7_respondable_coll_25.dae" />
            </geometry>
        </collision>
        <collision name="LR4_R560_link7_respondable">
            <origin xyz="-0.000154 0.000131 0.005256" rpy="-2.316304 1.571449 1.567710" />
            <geometry>
                <mesh filename="package://linghou_description/meshes/xarm7_with_gripper_LR4_R560_link7_respondable_coll_26.dae" />
            </geometry>
        </collision>
        <collision name="LR4_R560_link7_respondable">
            <origin xyz="-0.000154 0.000131 0.005256" rpy="-2.316304 1.571449 1.567710" />
            <geometry>
                <mesh filename="package://linghou_description/meshes/xarm7_with_gripper_LR4_R560_link7_respondable_coll_27.dae" />
            </geometry>
        </collision>
        <collision name="LR4_R560_link7_respondable">
            <origin xyz="-0.000154 0.000131 0.005256" rpy="-2.316304 1.571449 1.567710" />
            <geometry>
                <mesh filename="package://linghou_description/meshes/xarm7_with_gripper_LR4_R560_link7_respondable_coll_28.dae" />
            </geometry>
        </collision>
        <collision name="LR4_R560_link7_respondable">
            <origin xyz="-0.000154 0.000131 0.005256" rpy="-2.316304 1.571449 1.567710" />
            <geometry>
                <mesh filename="package://linghou_description/meshes/xarm7_with_gripper_LR4_R560_link7_respondable_coll_29.dae" />
            </geometry>
        </collision>
        <collision name="LR4_R560_link7_respondable">
            <origin xyz="-0.000154 0.000131 0.005256" rpy="-2.316304 1.571449 1.567710" />
            <geometry>
                <mesh filename="package://linghou_description/meshes/xarm7_with_gripper_LR4_R560_link7_respondable_coll_30.dae" />
            </geometry>
        </collision>
        <collision name="LR4_R560_link7_respondable">
            <origin xyz="-0.000154 0.000131 0.005256" rpy="-2.316304 1.571449 1.567710" />
            <geometry>
                <mesh filename="package://linghou_description/meshes/xarm7_with_gripper_LR4_R560_link7_respondable_coll_31.dae" />
            </geometry>
        </collision>
        <collision name="LR4_R560_link7_respondable">
            <origin xyz="-0.000154 0.000131 0.005256" rpy="-2.316304 1.571449 1.567710" />
            <geometry>
                <mesh filename="package://linghou_description/meshes/xarm7_with_gripper_LR4_R560_link7_respondable_coll_32.dae" />
            </geometry>
        </collision>
        <collision name="LR4_R560_link7_respondable">
            <origin xyz="-0.000154 0.000131 0.005256" rpy="-2.316304 1.571449 1.567710" />
            <geometry>
                <mesh filename="package://linghou_description/meshes/xarm7_with_gripper_LR4_R560_link7_respondable_coll_33.dae" />
            </geometry>
        </collision>
        <collision name="LR4_R560_link7_respondable">
            <origin xyz="-0.000154 0.000131 0.005256" rpy="-2.316304 1.571449 1.567710" />
            <geometry>
                <mesh filename="package://linghou_description/meshes/xarm7_with_gripper_LR4_R560_link7_respondable_coll_34.dae" />
            </geometry>
        </collision>
        <collision name="LR4_R560_link7_respondable">
            <origin xyz="-0.000154 0.000131 0.005256" rpy="-2.316304 1.571449 1.567710" />
            <geometry>
                <mesh filename="package://linghou_description/meshes/xarm7_with_gripper_LR4_R560_link7_respondable_coll_35.dae" />
            </geometry>
        </collision>
        <collision name="LR4_R560_link7_respondable">
            <origin xyz="-0.000154 0.000131 0.005256" rpy="-2.316304 1.571449 1.567710" />
            <geometry>
                <mesh filename="package://linghou_description/meshes/xarm7_with_gripper_LR4_R560_link7_respondable_coll_36.dae" />
            </geometry>
        </collision>
        <collision name="LR4_R560_link7_respondable">
            <origin xyz="-0.000154 0.000131 0.005256" rpy="-2.316304 1.571449 1.567710" />
            <geometry>
                <mesh filename="package://linghou_description/meshes/xarm7_with_gripper_LR4_R560_link7_respondable_coll_37.dae" />
            </geometry>
        </collision>
        <visual name="LR4_R560_link7_visual">
            <origin xyz="0.000012 0.000047 0.005250" rpy="-0.918595 1.570836 -1.164261" />
            <geometry>
                <mesh filename="package://linghou_description/meshes/xarm7_with_gripper_LR4_R560_link7_visual_vis_1.dae" />
            </geometry>
            <material name="LR4_R560_link7_visual_material">
                <color rgba="1.000000 1.000000 1.000000 1.0" />
            </material>
        </visual>
    </link>
    <joint type="fixed" name="joint_eef">
        <axis xyz="0 0 1" />
        <parent link="LR4_R560_link7_respondable" />
        <child link="link_eef_visual" />
        <origin xyz="-0.00015 0.00013 0.00526" rpy="-3.13438 1.59529 3.06020" />
    </joint>
    <link name="link_eef_visual">
        <visual name="link_eef_visual">
            <origin xyz="0.000000 0.000000 0.000000" rpy="-0.000000 -1.570796 0.000000" />
            <geometry>
                <box size="0.000500 0.000500 0.000500" />
            </geometry>
            <material name="link_eef_visual_material">
                <color rgba="1.000000 1.000000 1.000000 1.0" />
            </material>
        </visual>
    </link>
    <joint type="fixed" name="gripper_fix">
        <axis xyz="0 0 1" />
        <parent link="link_eef_visual" />
        <child link="xarm_gripper_base_link_respondable" />
        <origin xyz="0.000000 0.000000 0.000000" rpy="3.141593 3.141593 3.141593" />
    </joint>
    <link name="xarm_gripper_base_link_respondable">
        <inertial>
            <origin rpy="0.000000 -1.570796 0.000000" xyz="-0.048028 -0.001850 -0.000655" />
            <inertia iyy="0.00033072" iyz="-1.0975e-05" ixz="2.6537e-06" ixy="3.9292e-07" ixx="0.00047106" izz="0.00025642" />
            <mass value="0.54156" />
        </inertial>
        <collision name="xarm_gripper_base_link_respondable">
            <origin xyz="0.000000 0.000000 0.000000" rpy="0.000000 -1.570796 0.000000" />
            <geometry>
                <mesh filename="package://linghou_description/meshes/xarm7_with_gripper_xarm_gripper_base_link_respondable_coll_1.dae" />
            </geometry>
        </collision>
        <visual name="xarm_gripper_base_link_visual">
            <origin xyz="0.000000 0.000000 0.000000" rpy="0.000000 -1.570796 0.000000" />
            <geometry>
                <mesh filename="package://linghou_description/meshes/xarm7_with_gripper_xarm_gripper_base_link_visual_vis_1.dae" />
            </geometry>
            <material name="xarm_gripper_base_link_visual_material">
                <color rgba="1.000000 1.000000 1.000000 1.0" />
            </material>
        </visual>
    </link>
    <joint type="revolute" name="drive_joint">
        <axis xyz="0 0 1" />
        <limit effort="50.0" lower="0.0" velocity="2.0" upper="0.85" />
        <parent link="xarm_gripper_base_link_respondable" />
        <child link="left_outer_knuckle_respondable" />
        <origin xyz="-0.059098 0.035000 -0.000000" rpy="-3.141593 3.141593 -3.141593" />
    </joint>
    <link name="left_outer_knuckle_respondable">
        <inertial>
            <origin rpy="0.000000 -1.570796 0.000000" xyz="-0.015181 0.021559 0.000000" />
            <inertia iyy="6.6256e-06" iyz="-7.3008e-06" ixz="-1.1002e-17" ixy="-1.8803e-17" ixx="1.9111e-05" izz="1.3185e-05" />
            <mass value="0.033618" />
        </inertial>
        <collision name="left_outer_knuckle_respondable">
            <origin xyz="0.000000 0.000000 0.000000" rpy="0.000000 -1.570796 0.000000" />
            <geometry>
                <mesh filename="package://linghou_description/meshes/xarm7_with_gripper_left_outer_knuckle_respondable_coll_1.dae" />
            </geometry>
        </collision>
        <visual name="left_outer_knuckle_visual">
            <origin xyz="0.000000 0.000000 0.000000" rpy="0.000000 -1.570796 0.000000" />
            <geometry>
                <mesh filename="package://linghou_description/meshes/xarm7_with_gripper_left_outer_knuckle_visual_vis_1.dae" />
            </geometry>
            <material name="left_outer_knuckle_visual_material">
                <color rgba="0.753000 0.753000 0.753000 1.0" />
            </material>
        </visual>
    </link>
    <joint type="revolute" name="left_finger_joint">
        <axis xyz="0 0 1" />
        <limit effort="50.0" lower="0.0" velocity="2.0" upper="0.85" />
        <parent link="left_outer_knuckle_respondable" />
        <child link="left_finger_respondable" />
        <origin xyz="-0.042039 0.035465 -0.000000" rpy="-0.000000 3.141593 -0.000000" />
    </joint>
    <link name="left_finger_respondable">
        <inertial>
            <origin rpy="0.000000 1.570796 0.000000" xyz="0.029258 -0.016413 -0.000000" />
            <inertia iyy="1.7225e-05" iyz="4.6433e-06" ixz="6.9164e-18" ixy="-4.2156e-19" ixx="1.7493e-05" izz="5.1466e-06" />
            <mass value="0.048304" />
        </inertial>
        <collision name="left_finger_respondable">
            <origin xyz="0.000000 0.000000 0.000000" rpy="0.000000 1.570796 0.000000" />
            <geometry>
                <mesh filename="package://linghou_description/meshes/xarm7_with_gripper_left_finger_respondable_coll_1.dae" />
            </geometry>
        </collision>
        <visual name="left_finger_visual">
            <origin xyz="0.000000 0.000000 0.000000" rpy="0.000000 1.570796 0.000000" />
            <geometry>
                <mesh filename="package://linghou_description/meshes/xarm7_with_gripper_left_finger_visual_vis_1.dae" />
            </geometry>
            <material name="left_finger_visual_material">
                <color rgba="0.753000 0.753000 0.753000 1.0" />
            </material>
        </visual>
    </link>
    <joint type="revolute" name="left_inner_knuckle_joint">
        <axis xyz="0 0 1" />
        <limit effort="50.0" lower="0.0" velocity="2.0" upper="0.85" />
        <parent link="xarm_gripper_base_link_respondable" />
        <child link="left_inner_knuckle_respondable" />
        <origin xyz="-0.074098 0.020000 -0.000000" rpy="-3.141593 3.141593 -3.141593" />
    </joint>
    <link name="left_inner_knuckle_respondable">
        <inertial>
            <origin rpy="0.000000 -1.570796 0.000000" xyz="-0.026133 0.022047 0.000002" />
            <inertia iyy="6.0195508437519e-06" iyz="-2.7531681299172e-06" ixz="7.1910267050063e-11" ixy="6.0665132616007e-11" ixx="6.0949002427191e-06" izz="5.078620044799e-06" />
            <mass value="0.023012578125671" />
        </inertial>
        <collision name="left_inner_knuckle_respondable">
            <origin xyz="0.000000 0.000000 0.000000" rpy="0.000000 -1.570796 0.000000" />
            <geometry>
                <mesh filename="package://linghou_description/meshes/xarm7_with_gripper_left_inner_knuckle_respondable_coll_1.dae" />
            </geometry>
        </collision>
        <visual name="left_inner_knuckle_visual">
            <origin xyz="0.000000 0.000000 0.000000" rpy="0.000000 -1.570796 0.000000" />
            <geometry>
                <mesh filename="package://linghou_description/meshes/xarm7_with_gripper_left_inner_knuckle_visual_vis_1.dae" />
            </geometry>
            <material name="left_inner_knuckle_visual_material">
                <color rgba="0.753000 0.753000 0.753000 1.0" />
            </material>
        </visual>
    </link>
    <joint type="revolute" name="right_outer_knuckle_joint">
        <axis xyz="0 0 1" />
        <limit effort="50.0" lower="0.0" velocity="2.0" upper="0.85" />
        <parent link="xarm_gripper_base_link_respondable" />
        <child link="right_outer_knuckle_respondable" />
        <origin xyz="-0.059098 -0.035000 -0.000000" rpy="-0.000000 3.141593 -0.000000" />
    </joint>
    <link name="right_outer_knuckle_respondable">
        <inertial>
            <origin rpy="0.000000 1.570796 0.000000" xyz="0.015181 -0.021559 0.000000" />
            <inertia iyy="6.6256e-06" iyz="7.3008e-06" ixz="1.0986e-17" ixy="-1.8789e-17" ixx="1.9111e-05" izz="1.3185e-05" />
            <mass value="0.033618" />
        </inertial>
        <collision name="right_outer_knuckle_respondable">
            <origin xyz="-0.000000 0.000000 0.000000" rpy="0.000000 1.570796 0.000000" />
            <geometry>
                <mesh filename="package://linghou_description/meshes/xarm7_with_gripper_right_outer_knuckle_respondable_coll_1.dae" />
            </geometry>
        </collision>
        <visual name="right_outer_knuckle_visual">
            <origin xyz="-0.000000 0.000000 0.000000" rpy="0.000000 1.570796 0.000000" />
            <geometry>
                <mesh filename="package://linghou_description/meshes/xarm7_with_gripper_right_outer_knuckle_visual_vis_1.dae" />
            </geometry>
            <material name="right_outer_knuckle_visual_material">
                <color rgba="0.753000 0.753000 0.753000 1.0" />
            </material>
        </visual>
    </link>
    <joint type="revolute" name="right_finger_joint">
        <axis xyz="0 0 1" />
        <limit effort="50.0" lower="0.0" velocity="2.0" upper="0.85" />
        <parent link="right_outer_knuckle_respondable" />
        <child link="right_finger_respondable" />
        <origin xyz="0.042039 -0.035465 -0.000000" rpy="-0.000000 3.141593 -0.000000" />
    </joint>
    <link name="right_finger_respondable">
        <inertial>
            <origin rpy="0.000000 -1.570796 0.000000" xyz="-0.029258 0.016413 -0.000000" />
            <inertia iyy="1.7225e-05" iyz="-4.6435e-06" ixz="-7.5079e-18" ixy="-5.0014e-19" ixx="1.7493e-05" izz="5.1466e-06" />
            <mass value="0.048304" />
        </inertial>
        <collision name="right_finger_respondable">
            <origin xyz="0.000000 0.000000 0.000000" rpy="0.000000 -1.570796 0.000000" />
            <geometry>
                <mesh filename="package://linghou_description/meshes/xarm7_with_gripper_right_finger_respondable_coll_1.dae" />
            </geometry>
        </collision>
        <visual name="right_finger_visual">
            <origin xyz="0.000000 0.000000 0.000000" rpy="0.000000 -1.570796 0.000000" />
            <geometry>
                <mesh filename="package://linghou_description/meshes/xarm7_with_gripper_right_finger_visual_vis_1.dae" />
            </geometry>
            <material name="right_finger_visual_material">
                <color rgba="0.753000 0.753000 0.753000 1.0" />
            </material>
        </visual>
    </link>
    <joint type="revolute" name="right_inner_knuckle_joint">
        <axis xyz="0 0 1" />
        <limit effort="50.0" lower="0.0" velocity="2.0" upper="0.85" />
        <parent link="xarm_gripper_base_link_respondable" />
        <child link="right_inner_knuckle_respondable" />
        <origin xyz="-0.074098 -0.020000 -0.000000" rpy="-0.000000 3.141593 -0.000000" />
    </joint>
    <link name="right_inner_knuckle_respondable">
        <inertial>
            <origin rpy="0.000000 1.570796 0.000000" xyz="0.026133 -0.022047 -0.000002" />
            <inertia iyy="6.0197e-06" iyz="2.7531e-06" ixz="7.191e-11" ixy="-6.0665e-11" ixx="6.0949e-06" izz="5.0784e-06" />
            <mass value="0.023013" />
        </inertial>
        <collision name="right_inner_knuckle_respondable">
            <origin xyz="0.000000 0.000000 0.000000" rpy="0.000000 1.570796 0.000000" />
            <geometry>
                <mesh filename="package://linghou_description/meshes/xarm7_with_gripper_right_inner_knuckle_respondable_coll_1.dae" />
            </geometry>
        </collision>
        <visual name="right_inner_knuckle_visual">
            <origin xyz="0.000000 0.000000 0.000000" rpy="0.000000 1.570796 0.000000" />
            <geometry>
                <mesh filename="package://linghou_description/meshes/xarm7_with_gripper_right_inner_knuckle_visual_vis_1.dae" />
            </geometry>
            <material name="right_inner_knuckle_visual_material">
                <color rgba="0.753000 0.753000 0.753000 1.0" />
            </material>
        </visual>
    </link>
    <joint type="fixed" name="joint_tcp">
        <axis xyz="0 0 1" />
        <parent link="xarm_gripper_base_link_respondable" />
        <child link="link_tcp_visual" />
        <origin xyz="-0.172000 -0.000000 -0.000000" rpy="-3.141593 3.141593 -3.141593" />
    </joint>
    <link name="link_tcp_visual">
        <visual name="link_tcp_visual">
            <origin xyz="0.000000 0.000000 0.000000" rpy="0.000000 -1.570796 0.000000" />
            <geometry>
                <box size="0.000500 0.000500 0.000500" />
            </geometry>
            <material name="link_tcp_visual_material">
                <color rgba="1.000000 1.000000 1.000000 1.0" />
            </material>
        </visual>
    </link>
</robot>
